<?xml version="1.0"?>

<robot xmlns:xacro="http://www.ros.org/wiki/xacro" 
 	xmlns:sensor="http://playerstage.sourceforge.net/gazebo/xmlschema/#sensor"
    	xmlns:controller="http://playerstage.sourceforge.net/gazebo/xmlschema/#controller"
    	xmlns:interface="http://playerstage.sourceforge.net/gazebo/xmlschema/#interface"
	name="carroDeParo">

	<xacro:macro name="default_inertial" params="mass">
               <inertial>
                       <mass value="${mass}" />
                       <inertia ixx="0.00026627" ixy="0.0" ixz="0.0"
                                iyx="0.0" iyy="0.00026241" iyz="0.0"
                                izy="0.0" izz="0.00030483" />
               </inertial>
	</xacro:macro>
	
	<xacro:include filename="$(find plataforma_movil)/models/carroDeParo.gazebo" />

	<link name="base_link">
   		<visual>
     			<geometry>
      				<mesh filename="package://plataforma_movil/meshes/chasis.STL" scale="0.001 0.001 0.001"/>
     			</geometry>
			<origin rpy="1.5708 0 0" xyz="-0.425 0.3 0.04"/>
			<material name="white">
				<color rgba="1 1 1 1"/>
			</material>
   		</visual>
		<collision>
			<geometry>
      				<mesh filename="package://plataforma_movil/meshes/chasis.STL" scale="0.001 0.001 0.001"/>
			</geometry>
			<origin rpy="1.5708 0 0" xyz="-0.425 0.3 0.04"/>
		</collision>
		<inertial>
  			<mass value="11.27"/>
  			<inertia ixx="0.49" ixy="0.0" ixz="0.0" iyy="1.02" iyz="0.0" izx="0.0" izz="0.77"/>
		</inertial>
 	</link>

 	<link name="wheel_1">
   		<visual>
     			<geometry>
      				<mesh filename="package://plataforma_movil/meshes/Rueda.STL" scale="0.001 0.001 0.001"/>
     			</geometry>
			<origin rpy="0 0 0" xyz="-0.051 -0.051 -0.04"/>
   			<material name="black">
				<color rgba="0 0 0 1"/>
			</material>
		</visual>
		<collision>
			<geometry>
      				<mesh filename="package://plataforma_movil/meshes/Rueda.STL" scale="0.001 0.001 0.001"/>
			</geometry>
			<origin rpy="0 0 0" xyz="-0.051 -0.051 -0.04"/>
		</collision>
		<xacro:default_inertial mass="0.19"/>

 	</link>

 	<link name="wheel_2">
   		<visual>
     			<geometry>
      				<mesh filename="package://plataforma_movil/meshes/Rueda.STL" scale="0.001 0.001 0.001"/>
     			</geometry>
			<origin rpy="0 0 0" xyz="-0.051 -0.051 -0.04"/>
   			<material name="black"/>
   		</visual>
		<collision>
			<geometry>
      				<mesh filename="package://plataforma_movil/meshes/Rueda.STL" scale="0.001 0.001 0.001"/>
			</geometry>
			<origin rpy="0 0 0" xyz="-0.051 -0.051 -0.04"/>
		</collision>
		<xacro:default_inertial mass="0.19"/>

 	</link>
    
 	<link name="wheel_3">
   		<visual>
     			<geometry>
      				<mesh filename="package://plataforma_movil/meshes/Rueda.STL" scale="0.001 0.001 0.001"/>
     			</geometry>
			<origin rpy="0 0 0" xyz="-0.051 -0.051 0"/>
   			<material name="black"/>
   		</visual>
		<collision>
			<geometry>
      				<mesh filename="package://plataforma_movil/meshes/Rueda.STL" scale="0.001 0.001 0.001"/>
			</geometry>
			<origin rpy="0 0 0" xyz="-0.051 -0.051 0"/>
		</collision>
		<xacro:default_inertial mass="0.19"/>
 	</link>

 	<link name="wheel_4">
   		<visual>
     			<geometry>
      				<mesh filename="package://plataforma_movil/meshes/Rueda.STL" scale="0.001 0.001 0.001"/>
     			</geometry>
			<origin rpy="0 0 0" xyz="-0.051 -0.051 0"/>
   			<material name="black"/>
   		</visual>
		<collision>
			<geometry>
      				<mesh filename="package://plataforma_movil/meshes/Rueda.STL" scale="0.001 0.001 0.001"/>
			</geometry>
			<origin rpy="0 0 0" xyz="-0.051 -0.051 0"/>
		</collision>
		<xacro:default_inertial mass="0.19"/>
 	</link>
 	
	<link name="web_cam">
   		<visual>
     			<geometry>
      				<mesh filename="package://plataforma_movil/meshes/web_cam.STL" scale="0.01 0.01 0.01"/>
     			</geometry>
			<origin rpy="0 0 1.5708" xyz="0 0 0"/>
   			
   		</visual>
		<collision>
			<geometry>
      				<mesh filename="package://plataforma_movil/meshes/web_cam.STL" scale="0.01 0.01 0.01"/>
			</geometry>
			<origin rpy="0 0 1.5708" xyz="0 0 0"/>
		</collision>
		<inertial>
  			<mass value="0.001"/>
  			<inertia ixx="0.000001" ixy="0.000001" ixz="0.000001" iyy="0.000001" iyz="0.000001" izz="0.000001"/>
		</inertial>
 	</link>


 <joint name="base_to_wheel1" type="continuous">
   <parent link="base_link"/>
   <child link="wheel_1"/>
   <origin rpy="1.5708 0 0" xyz="0.305 0.27 0.055"/>
   <axis xyz="0 0 -1" />
<!-- <limit effort="1000" lower="-0.45" upper="0.45" velocity="0.45"/> -->
 </joint>

 <joint name="base_to_wheel2" type="continuous">
   <parent link="base_link"/>
   <child link="wheel_2"/>
   <origin rpy="1.5708 0 0" xyz="-0.305 0.27 0.055"/>
   <axis xyz="0 0 -1" />
</joint>

 <joint name="base_to_wheel3" type="continuous">
   <parent link="base_link"/>
   <child link="wheel_3"/>
   <origin rpy="1.5708 0 0" xyz="0.305 -0.27 0.055"/>
   <axis xyz="0 0 -1" />
<!-- <limit effort="1000" lower="-0.45" upper="0.45" velocity="0.45"/> -->
 </joint>

 <joint name="base_to_wheel4" type="continuous">
   <parent link="base_link"/>
   <child link="wheel_4"/>
   <origin rpy="1.5708 0 0" xyz="-0.305 -0.27 0.055"/>
   <axis xyz="0 0 -1" />
 </joint>
 
 <joint name="base_to_web_cam" type="fixed">
   <parent link="base_link"/>
   <child link="web_cam"/>
   <origin rpy="0 0 0" xyz="0.38 0 0.14"/>
 </joint>
 
<!-- Drive controller -->
<gazebo>
	<plugin name="wheel_drive_controller" filename="libgazebo_ros_diff_drive.so">
	
	  <!-- wheels -->
	  <num_wheel_pairs>2</num_wheel_pairs>
	  <left_joint>base_to_wheel1</left_joint>
	  <left_joint>base_to_wheel2</left_joint>
	  <right_joint>base_to_wheel3</right_joint>
	  <right_joint>base_to_wheel4</right_joint>
	
	  <!-- kinematics -->
	  <wheel_separation>0.54</wheel_separation>
	  <wheel_diameter>0.12</wheel_diameter>
	  <max_wheel_torque>20.0</max_wheel_torque>
	  <max_wheel_acceleration>1.0</max_wheel_acceleration>
	
	  <!-- odometry  --> 
	  <odometry_source>1</odometry_source>
	  <odometry_frame>odom</odometry_frame>
	  <robot_base_frame>base_footprint</robot_base_frame>
	
	  <!-- topic & re remappings -->
	  <ros>
		<namespace>/</namespace>
		<argument>/cmd_vel:=cmd_vel</argument>
		<argument>/odom:=odom</argument>
	  </ros>
	
	  <publishWheelTF>true</publishWheelTF>
	  <publish_odom>true</publish_odom>
	  <publish_odom_tf>true</publish_odom_tf>
	  <update_rate>30.0</update_rate>
	</plugin>
	
	</gazebo>

</robot> 
